Workbook

Sheet Top 300
A1: In scope | B1: Leveranciersnummer | C1: Leveranciersnaam | D1: Totaal # artikelen | E1: pdf | F1: tekst in mail | G1: via link in mail | H1: Nota
A2: X | B2: 3001044 | C2: ABENA BV | D2: 36 | F2: x
A3: X | B3: 3000096 | C3: ADDED PHARMA BV | D3: 22 | E3: x
A4: X | B4: 3000002 | C4: AKB GROOTVERBRUIK B.V. | D4: 20 | E4: x
A5: X | B5: 3000190 | C5: ALCON NEDERLAND BV | D5: 24 | F5: x
A6: X | B6: 3000395 | C6: ALCON NV | D6: 16 | F6: x
A7: X | B7: 3000431 | C7: ALPHEIOS | D7: 24 | E7: x
A8: X | B8: 3000132 | C8: ALPHEIOS BV | D8: 48 | E8: x
A9: X | B9: 3000019 | C9: AMBU BV | D9: 15 | E9: x
A10: X | B10: 3002833 | C10: AMBU BV Belgie | D10: 18 | E10: x
A11: X | B11: 3003735 | C11: APPLIED MEDICAL BELGIUM BV | D11: 7 | E11: x
A12: X | B12: 3000239 | C12: APPLIED MEDICAL BV | D12: 68 | E12: x
A13: X | B13: 3000003 | C13: ARGUS ETIKETTEN BV | D13: 24 | E13: x
A14: X | B14: 3001279 | C14: ARJO BELGIUM NV | D14: 6 | E14: x
A15: X | B15: 3000939 | C15: ARJO NEDERLAND BV | D15: 16 | E15: x
A16: X | B16: 3004411 | C16: ARSEUS MEDICAL GROUP BV | D16: 1 | E16: x
A17: X | B17: 3000687 | C17: ARSEUS MEDICAL GROUP NV | D17: 2 | E17: x
A18: X | B18: 3004318 | C18: ARSEUS MEDICAL GROUP NV AZ DIMPNA | D18: 7 | E18: x
... A24: X | B24: 3004338 | C24: ARSEUS MEDICAL GROUP NV WZC | D24: 6 | E24: x
A25: X | B25: 3002156 | C25: ARTHREX BVBA | D25: 14
A26: X | B26: 3001236 | C26: ARTHREX NEDERLAND BV | D26: 26
A27: X | B27: 3004380 | C27: AT MEDICALS BVBA AZ ST DIMPNA GEEL | D27: 3 | E27: x
A28: X | B28: 3004382 | C28: AT MEDICALS BVBA EMMAUS | D28: 2 | E28: x
A29: X | B29: 3004383 | C29: AT MEDICALS BVBA IMELDA | D29: 7 | E29: x
A30: X | B30: 3004381 | C30: AT MEDICALS BVBA SAL | D30: 16 | E30: x
A31: X | B31: 3000005 | C31: B. BRAUN MEDICAL BV | D31: 360 | E31: x | H31: AFW: bruto naar netto prijs
A32: X | B32: 3000465 | C32: B.BRAUN MEDICAL N.V. | D32: 186 | E32: x
A33: X | B33: 3002134 | C33: BAUSCH & LOMB BVBA | D33: 1 | F33: x
A34: X | B34: 3000966 | C34: BAUSCH EN LOMB SURGICAL | D34: 21 | F34: x
A35: X | B35: 3004257 | C35: BAXTER BE BVBA AZ ST DIMPNA | D35: 4 | F35: x
A36: X | B36: 3004260 | C36: BAXTER BE BVBA AZH | D36: 5 | F36: x
A37: X | B37: 3004256 | C37: BAXTER BE BVBA CHC | D37: 5 | F37: x
A38: X | B38: 3004255 | C38: BAXTER BE BVBA EMMAUS | D38: 1 | F38: x
A39: X | B39: 3004259 | C39: BAXTER BE BVBA IMELDA | D39: 8 | F39: x
A40: X | B40: 3004258 | C40: BAXTER BE BVBA SAL | D40: 4 | F40: x
A41: X | B41: 3000263 | C41: BAXTER BV | D41: 132 | F41: x
A42: X | B42: 3000952 | C42: BAYER HEALTHCARE | D42: 24 | F42: x
A43: X | B43: 3000008 | C43: BECTON DICKINSON BV | D43: 515 | E43: x | G43: x | H43: OB => alleen van art met LT?
A44: X | B44: 3003861 | C44: BECTON DICKINSON BV EU NL1033064313 | D44: 3 | E44: x | G44: x
A45: X | B45: 3000374 | C45: BECTON DICKINSON NV | D45: 316 | E45: x | G45: x
...

Sheet Analyse HL 2 (3)
E1: Classification | F1: Standard
E2: GPT-5 Nano | F2: GPT-5 Mini | G2: Hoover te voorzien
N3: Nuttig veld? | R3: Nuttig veld?
E4: =COUNTA(Table326[File Name]) -> 99 | F4: =COUNTIF(Table326[Recognised doc type],"extracted") -> 77 | G4: =SUM(Table326['# Missing fields]) -> 69 | H4: =AVERAGE(Table326[PO nr]) -> 0.95652174 | I4: =AVERAGE(Table326[Supplier Order Nr]) -> 0.91304348 | J4: =AVERAGE(Table326[Order Date]) -> 0.95652174 | K4: =AVERAGE(Table326[Supplier Name]) -> 0.95652174 | L4: =AVERAGE(Table326[Customer name]) -> 0.95652174 | M4: =AVERAGE(Table326[Currency]) -> 0.84782609 | N4: =AVERAGE(Table326[Line nr]) -> 0.91304348 | O4: =AVERAGE(Table326[Article Number]) -> 0.95652174 | P4: =AVERAGE(Table326[Description]) -> 0.93478261 | Q4: =AVERAGE(Table326[Quantity]) -> 0.95652174 | R4: =AVERAGE(Table326[UoM]) -> 0.80434783 | S4: =AVERAGE(Table326[Unit Price]) -> 0.7826087 | T4: =AVERAGE(Table326[Delivery Date]) -> 0.65217391 | U4: =AVERAGE(H4:T4) -> 0.89130435
H5: Confirmation Lines
D6: Customer | E6: File Name | F6: Recognised doc type | G6: # Missing fields | H6: PO nr | I6: Supplier Order Nr | J6: Order Date | K6: Supplier Name | L6: Customer name | M6: Currency | N6: Line nr | O6: Article Number | P6: Description | Q6: Quantity | R6: UoM | S6: Unit Price | T6: Delivery Date | U6: Avg | V6: Comments | W6: Vraag HL | X6: Acties | Y6: Beslissing | Z6: Flexso
C7: =_xlfn.XLOOKUP(Table326[[#This Row],[Customer]],'Top 300'!C:C,'Top 300'!A:A,"0",2,1) -> 0 | D7: =_xlfn.XLOOKUP(Table326[[#This Row],[File Name]],'Analyse 2 Detail 02-03'!A:A,'Analyse 2 Detail 02-03'!R:R,"Not Found",0,1) -> Mölnlycke Health Care NV | E7: _ Orderbevestiging 1501037327.pdf | F7: extracted | G7: 0 | U7: =AVERAGE(Table326[[#This Row],[PO nr]:[Delivery Date]]) -> #DIV/0!
C8: =_xlfn.XLOOKUP(Table326[[#This Row],[Customer]],'Top 300'!C:C,'Top 300'!A:A,"0",2,1) -> 0 | D8: =_xlfn.XLOOKUP(Table326[[#This Row],[File Name]],'Analyse 2 Detail 02-03'!A:A,'Analyse 2 Detail 02-03'!R:R,"Not Found",0,1) -> Mölnlycke Health Care B.V. | E8: _ Orderbevestiging 1504026582.pdf | F8: extracted | G8: 0 | U8: =AVERAGE(Table326[[#This Row],[PO nr]:[Delivery Date]]) -> #DIV/0!
C9: =_xlfn.XLOOKUP(Table326[[#This Row],[Customer]],'Top 300'!C:C,'Top 300'!A:A,"0",2,1) -> 0 | D9: =_xlfn.XLOOKUP(Table326[[#This Row],[File Name]],'Analyse 2 Detail 02-03'!A:A,'Analyse 2 Detail 02-03'!R:R,"Not Found",0,1) -> Mölnlycke Health Care B.V. | E9: _ Orderbevestiging 1505040022.pdf | F9: extracted | G9: 0 | U9: =AVERAGE(Table326[[#This Row],[PO nr]:[Delivery Date]]) -> #DIV/0!
C10: =_xlfn.XLOOKUP(Table326[[#This Row],[Customer]],'Top 300'!C:C,'Top 300'!A:A,"0",2,1) -> 0 | D10: =_xlfn.XLOOKUP(Table326[[#This Row],[File Name]],'Analyse 2 Detail 02-03'!A:A,'Analyse 2 Detail 02-03'!R:R,"Not Found",0,1) -> Mölnlycke Health Care B.V. | E10: _ Orderbevestiging 3504015911.pdf | F10: extracted | G10: 0 | U10: =AVERAGE(Table326[[#This Row],[PO nr]:[Delivery Date]]) -> #DIV/0!
C11: =_xlfn.XLOOKUP(Table326[[#This Row],[Customer]],'Top 300'!C:C,'Top 300'!A:A,"0",2,1) -> 0 | D11: =_xlfn.XLOOKUP(Table326[[#This Row],[File Name]],'Analyse 2 Detail 02-03'!A:A,'Analyse 2 Detail 02-03'!R:R,"Not Found",0,1) -> Mölnlycke Health Care B.V. | E11: _ Orderbevestiging 3505026677.pdf | F11: extracted | G11: 0 | U11: =AVERAGE(Table326[[#This Row],[PO nr]:[Delivery Date]]) -> #DIV/0!
C12: =_xlfn.XLOOKUP(Table326[[#This Row],[Customer]],'Top 300'!C:C,'Top 300'!A:A,"0",2,1) -> 0 | D12: =_xlfn.XLOOKUP(Table326[[#This Row],[File Name]],'Analyse 2 Detail 02-03'!A:A,'Analyse 2 Detail 02-03'!R:R,"Not Found",0,1) -> 0 | E12: 100142673 HL WZC Herinnering Sligro [#KM-6720322] [#RL-144746].pdf | F12: unclassified | G12: 0 | H12: N/A | I12: N/A | J12: N/A | K12: N/A | L12: N/A | M12: N/A | N12: N/A | O12: N/A | P12: N/A | Q12: N/A | R12: N/A | S12: N/A | T12: N/A | U12: =AVERAGE(Table326[[#This Row],[PO nr]:[Delivery Date]]) -> #DIV/0! | V12: Niet extracted want geen OB - Betalingsherinnering | W12: Deze proberen weren van OB mailbox
C13: =_xlfn.XLOOKUP(Table326[[#This Row],[Customer]],'Top 300'!C:C,'Top 300'!A:A,"0",2,1) -> X | D13: =_xlfn.XLOOKUP(Table326[[#This Row],[File Name]],'Analyse 2 Detail 02-03'!A:A,'Analyse 2 Detail 02-03'!R:R,"Not Found",0,1) -> Essity Belgium NV | E13: 2501209992 ESSITY Orderbevestiging.pdf | F13: extracted | G13: 0 | U13: =AVERAGE(Table326[[#This Row],[PO nr]:[Delivery Date]]) -> #DIV/0!
C14: =_xlfn.XLOOKUP(Table326[[#This Row],[Customer]],'Top 300'!C:C,'Top 300'!A:A,"0",2,1) -> X | D14: =_xlfn.XLOOKUP(Table326[[#This Row],[File Name]],'Analyse 2 Detail 02-03'!A:A,'Analyse 2 Detail 02-03'!R:R,"Not Found",0,1) -> Essity Belgium NV | E14: 2501209992 ESSITY Orderbevestiging.pdf | F14: extracted | G14: 0 | U14: =AVERAGE(Table326[[#This Row],[PO nr]:[Delivery Date]]) -> #DIV/0!
C15: =_xlfn.XLOOKUP(Table326[[#This Row],[Customer]],'Top 300'!C:C,'Top 300'!A:A,"0",2,1) -> 0 | D15: =_xlfn.XLOOKUP(Table326[[#This Row],[File Name]],'Analyse 2 Detail 02-03'!A:A,'Analyse 2 Detail 02-03'!R:R,"Not Found",0,1) -> Essity Netherlands B.V. | E15: 2505040799 ESSITY Order Ontvangstbevestiging.pdf | F15: extracted | G15: 1 | H15: 1 | I15: 1 | J15: 1 | K15: 1 | L15: 1 | M15: 1 | N15: 1 | O15: 1 | P15: 1 | Q15: 1 | R15: 1 | S15: 1 | T15: 0.5 | U15: =AVERAGE(Table326[[#This Row],[PO nr]:[Delivery Date]]) -> 0.96153846 | V15: Order ontvangst bevestiging =/= OB - Geen leverdatum | W15: Wat gaan we doen met order ontvangst bevestigingen?
C16: =_xlfn.XLOOKUP(Table326[[#This Row],[Customer]],'Top 300'!C:C,'Top 300'!A:A,"0",2,1) -> 0 | D16: =_xlfn.XLOOKUP(Table326[[#This Row],[File Name]],'Analyse 2 Detail 02-03'!A:A,'Analyse 2 Detail 02-03'!R:R,"Not Found",0,1) -> Essity Netherlands B.V. | E16: 2507017044 ESSITY Order Ontvangstbevestiging.pdf | F16: extracted | G16: 2 | H16: 1 | I16: 1 | J16: 1 | K16: 1 | L16: 1 | M16: 1 | N16: 1 | O16: 1 | P16: 1 | Q16: 1 | R16: 1 | S16: 1 | T16: 0.5 | U16: =AVERAGE(Table326[[#This Row],[PO nr]:[Delivery Date]]) -> 0.96153846 | V16: Order ontvangst bevestiging =/= OB - Geen leverdatum | W16: Wat gaan we doen met order ontvangst bevestigingen?
C17: =_xlfn.XLOOKUP(Table326[[#This Row],[Customer]],'Top 300'!C:C,'Top 300'!A:A,"0",2,1) -> X | D17: =_xlfn.XLOOKUP(Table326[[#This Row],[File Name]],'Analyse 2 Detail 02-03'!A:A,'Analyse 2 Detail 02-03'!R:R,"Not Found",0,1) -> Essity Belgium NV | E17: 2508010179 ESSITY Orderbevestiging.pdf | F17: extracted | G17: 4 | H17: 1 | I17: 1 | J17: 1 | K17: 1 | L17: 1 | M17: 1 | N17: 1 | O17: 1 | P17: 1 | Q17: 1 | R17: 1 | S17: 0.5 | T17: 0.5 | U17: =AVERAGE(Table326[[#This Row],[PO nr]:[Delivery Date]]) -> 0.92307692 | V17: Geen unit price op OB - Line 1: geen confirmed del date | W17: Wat willen we doen in geval niet confirmed? | X17: Te confirmeren indien geen delivery date veld leeg of altijd +1 dag tegenover bevestigingsdatum
C18: =_xlfn.XLOOKUP(Table326[[#This Row],[Customer]],'Top 300'!C:C,'Top 300'!A:A,"0",2,1) -> X | D18: =_xlfn.XLOOKUP(Table326[[#This Row],[File Name]],'Analyse 2 Detail 02-03'!A:A,'Analyse 2 Detail 02-03'!R:R,"Not Found",0,1) -> Essity Belgium NV | E18: 2508010179 ESSITY Orderbevestiging.pdf | F18: extracted | G18: 1 | H18: 1 | I18: 1 | J18: 1 | K18: 1 | L18: 1 | M18: 1 | N18: 1 | O18: 1 | P18: 1 | Q18: 1 | R18: 1 | S18: 1 | T18: 0.5 | U18: =AVERAGE(Table326[[#This Row],[PO nr]:[Delivery Date]]) -> 0.96153846 | V18: Zelfde OB als lijn 17 maar met prijzen - Line 1: geen confirmed del date | W18: Wat willen we doen in geval niet confirmed? | X18: Te confirmeren indien geen delivery date veld leeg of altijd +1 dag tegenover bevestigingsdatum
C19: =_xlfn.XLOOKUP(Table326[[#This Row],[Customer]],'Top 300'!C:C,'Top 300'!A:A,"0",2,1) -> 0 | D19: =_xlfn.XLOOKUP(Table326[[#This Row],[File Name]],'Analyse 2 Detail 02-03'!A:A,'Analyse 2 Detail 02-03'!R:R,"Not Found",0,1) -> Essity Netherlands B.V. Health & Medical | E19: 3505026639 ESSITY Orderbevestiging.pdf | F19: extracted | G19: 0 | U19: =AVERAGE(Table326[[#This Row],[PO nr]:[Delivery Date]]) -> #DIV/0!
C20: =_xlfn.XLOOKUP(Table326[[#This Row],[Customer]],'Top 300'!C:C,'Top 300'!A:A,"0",2,1) -> 0 | D20: =_xlfn.XLOOKUP(Table326[[#This Row],[File Name]],'Analyse 2 Detail 02-03'!A:A,'Analyse 2 Detail 02-03'!R:R,"Not Found",0,1) -> Essity Netherlands B.V. | E20: 3505026670 ESSITY Orderbevestiging.pdf | F20: extracted | G20: 0 | U20: =AVERAGE(Table326[[#This Row],[PO nr]:[Delivery Date]]) -> #DIV/0!
C21: =_xlfn.XLOOKUP(Table326[[#This Row],[Customer]],'Top 300'!C:C,'Top 300'!A:A,"0",2,1) -> 0 | D21: =_xlfn.XLOOKUP(Table326[[#This Row],[File Name]],'Analyse 2 Detail 02-03'!A:A,'Analyse 2 Detail 02-03'!R:R,"Not Found",0,1) -> Essity Netherlands B.V. | E21: 3505026678 ESSITY Orderbevestiging.pdf | F21: extracted | G21: 0 | U21: =AVERAGE(Table326[[#This Row],[PO nr]:[Delivery Date]]) -> #DIV/0!
C22: =_xlfn.XLOOKUP(Table326[[#This Row],[Customer]],'Top 300'!C:C,'Top 300'!A:A,"0",2,1) -> 0 | D22: =_xlfn.XLOOKUP(Table326[[#This Row],[File Name]],'Analyse 2 Detail 02-03'!A:A,'Analyse 2 Detail 02-03'!R:R,"Not Found",0,1) -> Essity Netherlands B.V. | E22: 6507004827 ESSITY Order Ontvangstbevestiging.pdf | F22: extracted | G22: 1 | H22: 1 | I22: 1 | J22: 1 | K22: 1 | L22: 1 | M22: 1 | N22: 1 | O22: 1 | P22: 1 | Q22: 1 | R22: 1 | S22: 1 | T22: 0.5 | U22: =AVERAGE(Table326[[#This Row],[PO nr]:[Delivery Date]]) -> 0.96153846 | V22: Order ontvangst bevestiging =/= OB - Geen leverdatum | W22: Wat gaan we doen met order ontvangst bevestigingen?
C23: =_xlfn.XLOOKUP(Table326[[#This Row],[Customer]],'Top 300'!C:C,'Top 300'!A:A,"0",2,1) -> 0 | D23: =_xlfn.XLOOKUP(Table326[[#This Row],[File Name]],'Analyse 2 Detail 02-03'!A:A,'Analyse 2 Detail 02-03'!R:R,"Not Found",0,1) -> Essity Netherlands B.V. | E23: 6507004831 ESSITY Order Ontvangstbevestiging.pdf | F23: extracted | G23: 1 | H23: 1 | I23: 1 | J23: 1 | K23: 1 | L23: 1 | M23: 1 | N23: 1 | O23: 1 | P23: 1 | Q23: 1 | R23: 1 | S23: 1 | T23: 0.5 | U23: =AVERAGE(Table326[[#This Row],[PO nr]:[Delivery Date]]) -> 0.96153846 | V23: Order ontvangst bevestiging =/= OB - Geen leverdatum | W23: Wat gaan we doen met order ontvangst bevestigingen?
C24: =_xlfn.XLOOKUP(Table326[[#This Row],[Customer]],'Top 300'!C:C,'Top 300'!A:A,"0",2,1) -> 0 | D24: =_xlfn.XLOOKUP(Table326[[#This Row],[File Name]],'Analyse 2 Detail 02-03'!A:A,'Analyse 2 Detail 02-03'!R:R,"Not Found",0,1) -> Essity Netherlands B.V. | E24: 6507004833 ESSITY Order Ontvangstbevestiging.pdf | F24: extracted | G24: 1 | H24: 1 | I24: 1 | J24: 1 | K24: 1 | L24: 1 | M24: 1 | N24: 1 | O24: 1 | P24: 1 | Q24: 1 | R24: 1 | S24: 1 | T24: 0.5 | U24: =AVERAGE(Table326[[#This Row],[PO nr]:[Delivery Date]]) -> 0.96153846 | V24: Order ontvangst bevestiging =/= OB - Geen leverdatum | W24: Wat gaan we doen met order ontvangst bevestigingen?
C25: =_xlfn.XLOOKUP(Table326[[#This Row],[Customer]],'Top 300'!C:C,'Top 300'!A:A,"0",2,1) -> X | D25: =_xlfn.XLOOKUP(Table326[[#This Row],[File Name]],'Analyse 2 Detail 02-03'!A:A,'Analyse 2 Detail 02-03'!R:R,"Not Found",0,1) -> Becton Dickinson BV | E25: BD Order Acknowledgement for your purchase order with reference 1505040027.pdf | F25: extracted | G25: 0 | U25: =AVERAGE(Table326[[#This Row],[PO nr]:[Delivery Date]]) -> #DIV/0!
C26: =_xlfn.XLOOKUP(Table326[[#This Row],[Customer]],'Top 300'!C:C,'Top 300'!A:A,"0",2,1) -> X | D26: =_xlfn.XLOOKUP(Table326[[#This Row],[File Name]],'Analyse 2 Detail 02-03'!A:A,'Analyse 2 Detail 02-03'!R:R,"Not Found",0,1) -> Becton Dickinson BV | E26: BD Order Acknowledgement for your purchase order with reference 3504015923.pdf | F26: extracted | G26: 0 | U26: =AVERAGE(Table326[[#This Row],[PO nr]:[Delivery Date]]) -> #DIV/0!
C27: =_xlfn.XLOOKUP(Table326[[#This Row],[Customer]],'Top 300'!C:C,'Top 300'!A:A,"0",2,1) -> X | D27: =_xlfn.XLOOKUP(Table326[[#This Row],[File Name]],'Analyse 2 Detail 02-03'!A:A,'Analyse 2 Detail 02-03'!R:R,"Not Found",0,1) -> Becton Dickinson BV | E27: BD Order Acknowledgement for your purchase order with reference 3507009726.pdf | F27: extracted | G27: 2 | H27: 1 | I27: 1 | J27: 1 | K27: 1 | L27: 1 | M27: 1 | N27: 1 | O27: 1 | P27: 1 | Q27: 1 | R27: 0.5 | S27: 1 | T27: 1 | U27: =AVERAGE(Table326[[#This Row],[PO nr]:[Delivery Date]]) -> 0.96153846 | V27: Geen UoM op OB | W27: Confirmeren op UoM in PO? To Check? | X27: Te confirmeren indien geen UOM maar quantity matcht - UOM van PO overnemen of to check?
C28: =_xlfn.XLOOKUP(Table326[[#This Row],[Customer]],'Top 300'!C:C,'Top 300'!A:A,"0",2,1) -> 0 | D28: =_xlfn.XLOOKUP(Table326[[#This Row],[File Name]],'Analyse 2 Detail 02-03'!A:A,'Analyse 2 Detail 02-03'!R:R,"Not Found",0,1) -> Medline Int'l Belgium BV | E28: BE356233 Order Hospital Logistics 1501037350.pdf | F28: extracted | G28: 2 | H28: 1 | I28: 1 | J28: 1 | K28: 1 | L28: 1 | M28: 1 | N28: 1 | O28: 1 | P28: 0.5 | Q28: 1 | R28: 0.5 | S28: 1 | T28: 1 | U28: =AVERAGE(Table326[[#This Row],[PO nr]:[Delivery Date]]) -> 0.92307692 | V28: Geen description & UoM op OB | W28: Wat willen we hiermee doen? | X28: Te confirmeren indien geen UOM maar quantity matcht - UOM van PO overnemen of to check? Te confirmeren indien geen description maar lev. Art. Nr matcht - Description van PO overnemen of to check?
C29: =_xlfn.XLOOKUP(Table326[[#This Row],[Customer]],'Top 300'!C:C,'Top 300'!A:A,"0",2,1) -> 0 | D29: =_xlfn.XLOOKUP(Table326[[#This Row],[File Name]],'Analyse 2 Detail 02-03'!A:A,'Analyse 2 Detail 02-03'!R:R,"Not Found",0,1) -> VYGON NEDERLAND B.V. | E29: Betreft_ Overzicht van nog te leveren Vygon producten.pdf | F29: unclassified | G29: 0 | U29: =AVERAGE(Table326[[#This Row],[PO nr]:[Delivery Date]]) -> #DIV/0!
C30: =_xlfn.XLOOKUP(Table326[[#This Row],[Customer]],'Top 300'!C:C,'Top 300'!A:A,"0",2,1) -> 0 | D30: =_xlfn.XLOOKUP(Table326[[#This Row],[File Name]],'Analyse 2 Detail 02-03'!A:A,'Analyse 2 Detail 02-03'!R:R,"Not Found",0,1) -> VYGON NEDERLAND B.V. | E30: Betreft_ Overzicht van nog te leveren Vygon producten.pdf | F30: unclassified | G30: 0 | U30: =AVERAGE(Table326[[#This Row],[PO nr]:[Delivery Date]]) -> #DIV/0!
C31: =_xlfn.XLOOKUP(Table326[[#This Row],[Customer]],'Top 300'!C:C,'Top 300'!A:A,"0",2,1) -> 0 | D31: =_xlfn.XLOOKUP(Table326[[#This Row],[File Name]],'Analyse 2 Detail 02-03'!A:A,'Analyse 2 Detail 02-03'!R:R,"Not Found",0,1) -> VYGON NEDERLAND B.V. | E31: Betreft_ Overzicht van nog te leveren Vygon producten.pdf | F31: extracted | G31: 3 | H31: 1 | I31: 1 | J31: 1 | K31: 1 | L31: 1 | M31: 0.5 | N31: 1 | O31: 1 | P31: 1 | Q31: 1 | R31: 0.5 | S31: 0.5 | T31: 1 | U31: =AVERAGE(Table326[[#This Row],[PO nr]:[Delivery Date]]) -> 0.88461538 | V31: Backorder overzicht - Geen currency, UoM of Unit Price op vermeld | W31: Wat doen we met deze bestanden? | X31: Te confirmeren indien geen unit price --> To check of overnemen van PO? Te confirmeren indien geen currency --> To check of overnemen van PO?
C32: =_xlfn.XLOOKUP(Table326[[#This Row],[Customer]],'Top 300'!C:C,'Top 300'!A:A,"0",2,1) -> 0 | D32: =_xlfn.XLOOKUP(Table326[[#This Row],[File Name]],'Analyse 2 Detail 02-03'!A:A,'Analyse 2 Detail 02-03'!R:R,"Not Found",0,1) -> King Belgium SA/NV | E32: Bevestiging bestelling S09313425-1.pdf | F32: extracted | G32: 0 | U32: =AVERAGE(Table326[[#This Row],[PO nr]:[Delivery Date]]) -> #DIV/0!
C33: =_xlfn.XLOOKUP(Table326[[#This Row],[Customer]],'Top 300'!C:C,'Top 300'!A:A,"0",2,1) -> 0 | D33: =_xlfn.XLOOKUP(Table326[[#This Row],[File Name]],'Analyse 2 Detail 02-03'!A:A,'Analyse 2 Detail 02-03'!R:R,"Not Found",0,1) -> King Belgium SA/NV | E33: Bevestiging bestelling S09313437-1.pdf | F33: extracted | G33: 0 | U33: =AVERAGE(Table326[[#This Row],[PO nr]:[Delivery Date]]) -> #DIV/0!
C34: =_xlfn.XLOOKUP(Table326[[#This Row],[Customer]],'Top 300'!C:C,'Top 300'!A:A,"0",2,1) -> 0 | D34: =_xlfn.XLOOKUP(Table326[[#This Row],[File Name]],'Analyse 2 Detail 02-03'!A:A,'Analyse 2 Detail 02-03'!R:R,"Not Found",0,1) -> King Belgium SA/NV | E34: Bevestiging bestelling S09313444-1.pdf | F34: extracted | G34: 0 | U34: =AVERAGE(Table326[[#This Row],[PO nr]:[Delivery Date]]) -> #DIV/0!
C35: =_xlfn.XLOOKUP(Table326[[#This Row],[Customer]],'Top 300'!C:C,'Top 300'!A:A,"0",2,1) -> 0 | D35: =_xlfn.XLOOKUP(Table326[[#This Row],[File Name]],'Analyse 2 Detail 02-03'!A:A,'Analyse 2 Detail 02-03'!R:R,"Not Found",0,1) -> King Belgium SA/NV | E35: Bevestiging bestelling S09313481-1.pdf | F35: extracted | G35: 0 | U35: =AVERAGE(Table326[[#This Row],[PO nr]:[Delivery Date]]) -> #DIV/0!
C36: =_xlfn.XLOOKUP(Table326[[#This Row],[Customer]],'Top 300'!C:C,'Top 300'!A:A,"0",2,1) -> 0 | D36: =_xlfn.XLOOKUP(Table326[[#This Row],[File Name]],'Analyse 2 Detail 02-03'!A:A,'Analyse 2 Detail 02-03'!R:R,"Not Found",0,1) -> King Belgium SA/NV | E36: Bevestiging bestelling S09313926-1.pdf | F36: extracted | G36: 1 | H36: 1 | I36: 1 | J36: 1 | K36: 1 | L36: 1 | M36: 1 | N36: 0 | O36: 1 | P36: 1 | Q36: 1 | R36: 1 | S36: 1 | T36: 1 | U36: =AVERAGE(Table326[[#This Row],[PO nr]:[Delivery Date]]) -> 0.92307692 | V36: KM heffing niet opgenomen in confirmation lines | X36: Te confirmeren dat we de KM-heffing negeren
C37: =_xlfn.XLOOKUP(Table326[[#This Row],[Customer]],'Top 300'!C:C,'Top 300'!A:A,"0",2,1) -> 0 | D37: =_xlfn.XLOOKUP(Table326[[#This Row],[File Name]],'Analyse 2 Detail 02-03'!A:A,'Analyse 2 Detail 02-03'!R:R,"Not Found",0,1) -> King Belgium SA/NV | E37: Bevestiging bestelling S09313928-1.pdf | F37: extracted | G37: 0 | U37: =AVERAGE(Table326[[#This Row],[PO nr]:[Delivery Date]]) -> #DIV/0!
C38: =_xlfn.XLOOKUP(Table326[[#This Row],[Customer]],'Top 300'!C:C,'Top 300'!A:A,"0",2,1) -> 0 | D38: =_xlfn.XLOOKUP(Table326[[#This Row],[File Name]],'Analyse 2 Detail 02-03'!A:A,'Analyse 2 Detail 02-03'!R:R,"Not Found",0,1) -> Duomed Belgium NV/SA | E38: Confirmation C007-S2607613-1.pdf | F38: extracted | G38: 0 | U38: =AVERAGE(Table326[[#This Row],[PO nr]:[Delivery Date]]) -> #DIV/0!
C39: =_xlfn.XLOOKUP(Table326[[#This Row],[Customer]],'Top 300'!C:C,'Top 300'!A:A,"0",2,1) -> 0 | D39: =_xlfn.XLOOKUP(Table326[[#This Row],[File Name]],'Analyse 2 Detail 02-03'!A:A,'Analyse 2 Detail 02-03'!R:R,"Not Found",0,1) -> King Belgium SA/NV | E39: Confirmation Commande S09313483-1.pdf | F39: extracted | G39: 0 | U39: =AVERAGE(Table326[[#This Row],[PO nr]:[Delivery Date]]) -> #DIV/0!
C40: =_xlfn.XLOOKUP(Table326[[#This Row],[Customer]],'Top 300'!C:C,'Top 300'!A:A,"0",2,1) -> 0 | D40: =_xlfn.XLOOKUP(Table326[[#This Row],[File Name]],'Analyse 2 Detail 02-03'!A:A,'Analyse 2 Detail 02-03'!R:R,"Not Found",0,1) -> 0 | E40: Embal.bon_100726_Sligro_5061_klant_000142470.pdf | F40: unclassified | G40: 0 | H40: N/A | I40: N/A | J40: N/A | K40: N/A | L40: N/A | M40: N/A | N40: N/A | O40: N/A | P40: N/A | Q40: N/A | R40: N/A | S40: N/A | T40: N/A | U40: =AVERAGE(Table326[[#This Row],[PO nr]:[Delivery Date]]) -> #DIV/0! | V40: Niet extracted want geen OB - Volgoed- en emballagebon | W40: Deze proberen weren van OB mailbox
...

Sheet SAPUI5 Export
A1: File Name | B1: Document Type | C1: Type Confidence | D1: Status | E1: Uploaded (UTC) | F1: File Size | G1: File Type | H1: Missing Fields | I1: Low Confidence Fields
A2: G3 Medical - per klant (Gelre) - 3504015927.pdf | C2: 88 | D2: extracted | E2: 46071.665 | F2: 111303 | G2: application/pdf | H2: 0 | I2: 0
A3: Essity BE - eerst ontvangstbevestiging - 2508010179.pdf | C3: 85 | D3: extracted | E3: 46071.665 | F3: 140250 | G3: application/pdf | H3: 6 | I3: 0
A4: Lyreco NL - nooit LT vermeld.pdf | C4: 85 | D4: extracted | E4: 46071.665 | F4: 16242 | G4: application/pdf | H4: 14 | I4: 0
A5: Medtronic NL - OB niet voor HL - rechtstreeks voor klant.PDF | C5: 92 | D5: extracted | E5: 46071.665 | F5: 22869 | G5: application/pdf | H5: 1 | I5: 0
A6: Essity BE - OB met prijzen - 2508010179.pdf | C6: 85 | D6: extracted | E6: 46071.665 | F6: 142035 | G6: application/pdf | H6: 1 | I6: 0
A7: Brocacef - per klant (Isala) - info update artikel besteld op andere PO - 3504015919.PDF | C7: 92 | D7: extracted | E7: 46071.665 | F7: 80430 | G7: application/pdf | H7: 30 | I7: 0
A8: Brocacef - per klant (Gelre) - info update artikel besteld op andere PO_3504015919.PDF | C8: 88 | D8: extracted | E8: 46071.665 | F8: 78681 | G8: application/pdf | H8: 12 | I8: 0
A9: Essity BE - OB zonder prijzen - 2508010179.pdf | C9: 90 | D9: extracted | E9: 46071.665 | F9: 140505 | G9: application/pdf | H9: 4 | I9: 0
A10: Cardinal Health BE - nooit LT vermeld.PDF | C10: 85 | D10: extracted | E10: 46071.665 | F10: 21165 | G10: application/pdf | H10: 0 | I10: 0
A11: G3 Medical - per klant (Isala) met afwijkende LT - 3504015927.pdf | C11: 85 | D11: extracted | E11: 46071.665 | F11: 112647 | G11: application/pdf | H11: 0 | I11: 0
A12: Essity NL - art lev niet exact - 2507016986.pdf | C12: 88 | D12: extracted | E12: 46071.665 | F12: 141015 | G12: application/pdf | H12: 0 | I12: 0
A13: B. Braun NL - bruto naar netto prijs.pdf | C13: 90 | D13: extracted | E13: 46071.665 | F13: 68516 | G13: application/pdf | H13: 0 | I13: 0
... A22: QRS - op klant - leverweek Isala - 3504015936.pdf | C22: 85 | D22: extracted | E22: 46071.647 | F22: 314184 | G22: application/pdf | H22: 1 | I22: 0

Sheet Analyse 1 Documents 27-02
A1: File Name | B1: Document Type | C1: Type Confidence | D1: Status | E1: Uploaded (UTC) | F1: File Size | G1: File Type | H1: Missing Fields | I1: Low Confidence Fields
A2: _ Orderbevestiging 1501037327.pdf | C2: 88 | D2: extracted | E2: 46080.531 | F2: 35061 | G2: application/pdf | H2: 0 | I2: 13
A3: _ Orderbevestiging 1504026582.pdf | C3: 82 | D3: extracted | E3: 46080.531 | F3: 34837 | G3: application/pdf | H3: 0 | I3: 0
A4: _ Orderbevestiging 1505040022.pdf | C4: 90 | D4: extracted | E4: 46080.531 | F4: 35265 | G4: application/pdf | H4: 0 | I4: 0
A5: _ Orderbevestiging 3504015911.pdf | C5: 85 | D5: extracted | E5: 46080.531 | F5: 58986 | G5: application/pdf | H5: 0 | I5: 255
A6: _ Orderbevestiging 3505026677.pdf | C6: 92 | D6: extracted | E6: 46080.531 | F6: 35794 | G6: application/pdf | H6: 0 | I6: 0
A7: 100142673 HL WZC Herinnering Sligro [#KM-6720322] [#RL-144746].pdf | C7: 28 | D7: unclassified | E7: 46080.531 | F7: 105937 | G7: application/pdf | H7: 0 | I7: 0
A8: 2501209992 ESSITY Orderbevestiging.pdf | C8: 92 | D8: extracted | E8: 46080.531 | F8: 138975 | G8: application/pdf | H8: 0 | I8: 12
A9: 2501209992 ESSITY Orderbevestiging.pdf | C9: 92 | D9: extracted | E9: 46080.531 | F9: 139995 | G9: application/pdf | H9: 0 | I9: 0
A10: 2505040799 ESSITY Order Ontvangstbevestiging.pdf | C10: 88 | D10: extracted | E10: 46080.531 | F10: 139995 | G10: application/pdf | H10: 1 | I10: 0
A11: 2507017044 ESSITY Order Ontvangstbevestiging.pdf | C11: 88 | D11: extracted | E11: 46080.531 | F11: 140760 | G11: application/pdf | H11: 2 | I11: 0
A12: 2508010179 ESSITY Orderbevestiging.pdf | C12: 92 | D12: extracted | E12: 46080.531 | F12: 140505 | G12: application/pdf | H12: 4 | I12: 0
A13: 2508010179 ESSITY Orderbevestiging.pdf | C13: 85 | D13: extracted | E13: 46080.531 | F13: 142035 | G13: application/pdf | H13: 1 | I13: 0
... A100: Verkooporder SO00454663 _ 3504015927.pdf | C100: 85 | D100: extracted | E100: 46080.531 | F100: 372936 | G100: application/pdf | H100: 0 | I100: 60

Sheet Analyse 2 Detail 02-03
E1: =AVERAGE(E3:E495) -> 73.435233 | G1: =AVERAGE(G3:G495) -> 0.5010142 | M1: =AVERAGE(M3:M126) -> 61.080645 | O1: =AVERAGE(O3:O126) -> 62.822581 | Q1: =AVERAGE(Q3:Q126) -> 63.129032 | S1: =AVERAGE(S3:S126) -> 62.879032 | U1: =AVERAGE(U3:U126) -> 62.185484 | W1: =AVERAGE(W3:W126) -> 62.685484 | Y1: =AVERAGE(Y3:Y126) -> 62.975806 | AA1: =AVERAGE(AA3:AA126) -> 62.403226 | AC1: =AVERAGE(AC3:AC126) -> 61.209677 | AE1: =AVERAGE(AE3:AE126) -> 63.016129 | AG1: =AVERAGE(AG3:AG126) -> 61.153226 | AI1: =AVERAGE(AI3:AI126) -> 61 | AK1: =AVERAGE(AK3:AK33) -> 70.903226
A2: File Name | B2: Document Type | C2: Status | D2: Uploaded (UTC) | E2: Extraction Score | F2: Total Fields | G2: Missing Fields | H2: Reviewed By | I2: Source | J2: Language | K2: Line Item # | L2: Purchase Order Number | M2: Purchase Order Number (Confidence %) | N2: Supplier Order Number | O2: Supplier Order Number (Confidence %) | P2: Order Date | Q2: Order Date (Confidence %) | R2: Supplier Name | S2: Supplier Name (Confidence %) | T2: Customer Name | U2: Customer Name (Confidence %) | V2: Currency | W2: Currency (Confidence %) | X2: Line Number | Y2: Line Number (Confidence %) | Z2: Article Number | AA2: Article Number (Confidence %) | AB2: Item Description | AC2: Item Description (Confidence %) | AD2: Quantity | AE2: Quantity (Confidence %) | AF2: Unit of Measure | AG2: Unit of Measure (Confidence %) | AH2: Unit Price | AI2: Unit Price (Confidence %) | AJ2: Item Planned Delivery Date | AK2: Item Planned Delivery Date (Confidence %)
A3: Uw orderbevestiging 60392040.pdf | B3: Purchase Order Confirmation | C3: extracted | D3: 46080.56 | E3: 93.8 | F3: 13 | G3: 0 | I3: mail - noreply@qrs.nl — Uw orderbevestiging 60392040 | J3: Dutch | K3: 1 | L3: 1505040024 | M3: 95 | N3: 60392040 | O3: 90 | P3: 16/02/2026 | Q3: 98 | R3: QRS Healthcare BV | S3: 92 | T3: Hospital Logistics Nederland BV (Bernhoven) | U3: 94 | V3: EUR | W3: 96 | X3: 1 | Y3: 90 | Z3: 54758 | AA3: 98 | AB3: Dispo Medical Cystoscopie enkel (50 stuks) | AC3: 96 | AD3: 5 | AE3: 98 | AF3: DS | AG3: 92 | AH3: EUR 166,21 | AI3: 95 | AJ3: 20/02/2026 | AK3: 92
A4: Verkooporder SO00454632 _ 3505026682.pdf | B4: Purchase Order Confirmation | C4: extracted | D4: 46080.56 | E4: 90.83 | F4: 104 | G4: 0 | I4: mail - info@g3-medical.nl — Verkooporder SO00454632 / 3505026682 | J4: Dutch | K4: 1 | L4: 3505026682 | M4: 98 | N4: SO00454632 | O4: 95 | P4: 16/02/2026 | Q4: 95 | R4: G3 Medical B.V. | S4: 95 | T4: Hospital Logistics Nederland B.V. | U4: 92 | V4: EUR | W4: 95 | X4: 1 | Y4: 95 | Z4: BP30F | AA4: 95 | AB4: Kai biopsie punch, disposable, steriel, 3,0mm, 20x1st/ds | AC4: 92 | AD4: 5 | AE4: 95 | AF4: Dozen | AG4: 92 | AH4: 25,15 | AI4: 92 | AJ4: 19/02/2026 | AK4: 90
A5: Verkooporder SO00454632 _ 3505026682.pdf | B5: Purchase Order Confirmation | C5: extracted | D5: 46080.56 | E5: 90.83 | F5: 104 | G5: 0 | I5: mail - info@g3-medical.nl — Verkooporder SO00454632 / 3505026682 | J5: Dutch | K5: 2 | L5: 3505026682 | M5: 98 | N5: SO00454632 | O5: 95 | P5: 16/02/2026 | Q5: 95 | R5: G3 Medical B.V. | S5: 95 | T5: Hospital Logistics Nederland B.V. | U5: 92 | V5: EUR | W5: 95 | X5: 2 | Y5: 95 | Z5: MK407 | AA5: 95 | AB5: Kai ring curette, disposable, steriel, 7,0mm, 20x1st/ds | AC5: 90 | AD5: 3 | AE5: 95 | AF5: Dozen | AG5: 92 | AH5: 33,31 | AI5: 92 | AJ5: 19/02/2026 | AK5: 90
A6: Verkooporder SO00454632 _ 3505026682.pdf | B6: Purchase Order Confirmation | C6: extracted | D6: 46080.56 | E6: 90.83 | F6: 104 | G6: 0 | I6: mail - info@g3-medical.nl — Verkooporder SO00454632 / 3505026682 | J6: Dutch | K6: 3 | L6: 3505026682 | M6: 98 | N6: SO00454632 | O6: 95 | P6: 16/02/2026 | Q6: 95 | R6: G3 Medical B.V. | S6: 95 | T6: Hospital Logistics Nederland B.V. | U6: 92 | V6: EUR | W6: 95 | X6: 3 | Y6: 95 | Z6: BP50F | AA6: 95 | AB6: Kai biopsie punch, disposable, steriel, 5,0mm, 20x1st/ds | AC6: 90 | AD6: 1 | AE6: 95 | AF6: Dozen | AG6: 92 | AH6: 26,07 | AI6: 92 | AJ6: 19/02/2026 | AK6: 90
A7: Verkooporder SO00454632 _ 3505026682.pdf | B7: Purchase Order Confirmation | C7: extracted | D7: 46080.56 | E7: 90.83 | F7: 104 | G7: 0 | I7: mail - info@g3-medical.nl — Verkooporder SO00454632 / 3505026682 | J7: Dutch | K7: 4 | L7: 3505026682 | M7: 98 | N7: SO00454632 | O7: 95 | P7: 16/02/2026 | Q7: 95 | R7: G3 Medical B.V. | S7: 95 | T7: Hospital Logistics Nederland B.V. | U7: 92 | V7: EUR | W7: 95 | X7: 4 | Y7: 95 | Z7: 700635 | AA7: 95 | AB7: Medicijnbeker 30ml, disposable, transparant, 100st/ds | AC7: 88 | AD7: 3 | AE7: 95 | AF7: Dozen | AG7: 90 | AH7: 30,79 | AI7: 92 | AJ7: 19/02/2026 | AK7: 90
A8: Verkooporder SO00454632 _ 3505026682.pdf | B8: Purchase Order Confirmation | C8: extracted | D8: 46080.56 | E8: 90.83 | F8: 104 | G8: 0 | I8: mail - info@g3-medical.nl — Verkooporder SO00454632 / 3505026682 | J8: Dutch | K8: 5 | L8: 3505026682 | M8: 98 | N8: SO00454632 | O8: 95 | P8: 16/02/2026 | Q8: 95 | R8: G3 Medical B.V. | S8: 95 | T8: Hospital Logistics Nederland B.V. | U8: 92 | V8: EUR | W8: 95 | X8: 5 | Y8: 95 | Z8: 300205 | AA8: 95 | AB8: CMT Identificatie foambandje, baby, disposable, X-Large, wit, 24st/doos | AC8: 92 | AD8: 4 | AE8: 95 | AF8: Dozen | AG8: 92 | AH8: 53,08 | AI8: 92 | AJ8: 19/02/2026 | AK8: 90
A9: Verkooporder SO00454632 _ 3505026682.pdf | B9: Purchase Order Confirmation | C9: extracted | D9: 46080.56 | E9: 90.83 | F9: 104 | G9: 0 | I9: mail - info@g3-medical.nl — Verkooporder SO00454632 / 3505026682 | J9: Dutch | K9: 6 | L9: 3505026682 | M9: 98 | N9: SO00454632 | O9: 95 | P9: 16/02/2026 | Q9: 95 | R9: G3 Medical B.V. | S9: 95 | T9: Hospital Logistics Nederland B.V. | U9: 92 | V9: EUR | W9: 95 | X9: 6 | Y9: 95 | Z9: 700747 | AA9: 95 | AB9: Medi-inn scheermesje, dubbel-edged, disposable, blauw, 100st/doos | AC9: 90 | AD9: 2 | AE9: 95 | AF9: Dozen | AG9: 92 | AH9: 9,13 | AI9: 92 | AJ9: 19/02/2026 | AK9: 90
A10: Verkooporder SO00454632 _ 3505026682.pdf | B10: Purchase Order Confirmation | C10: extracted | D10: 46080.56 | E10: 90.83 | F10: 104 | G10: 0 | I10: mail - info@g3-medical.nl — Verkooporder SO00454632 / 3505026682 | J10: Dutch | K10: 7 | L10: 3505026682 | M10: 98 | N10: SO00454632 | O10: 95 | P10: 16/02/2026 | Q10: 95 | R10: G3 Medical B.V. | S10: 95 | T10: Hospital Logistics Nederland B.V. | U10: 92 | V10: EUR | W10: 95 | X10: 7 | Y10: 95 | Z10: 700555 | AA10: 95 | AB10: Waca drinkbeker, PP, 250ml, semi-transparent, p/st | AC10: 88 | AD10: 2 | AE10: 95 | AF10: Stuks | AG10: 90 | AH10: 1,09 | AI10: 92 | AJ10: 19/02/2026 | AK10: 90
A11: Verkooporder SO00454632 _ 3505026682.pdf | B11: Purchase Order Confirmation | C11: extracted | D11: 46080.56 | E11: 90.83 | F11: 104 | G11: 0 | I11: mail - info@g3-medical.nl — Verkooporder SO00454632 / 3505026682 | J11: Dutch | K11: 8 | L11: 3505026682 | M11: 98 | N11: SO00454632 | O11: 95 | P11: 16/02/2026 | Q11: 95 | R11: G3 Medical B.V. | S11: 95 | T11: Hospital Logistics Nederland B.V. | U11: 92 | V11: EUR | W11: 95 | X11: 8 | Y11: 95 | Z11: 704400 | AA11: 95 | AB11: CMT Telemetrie draagtasjes, disposable, 21x16,5cm, PP/PE met lintfreeband, wit,100st/doos | AC11: 90 | AD11: 4 | AE11: 95 | AF11: Dozen | AG11: 92 | AH11: 52,08 | AI11: 92 | AJ11: 19/02/2026 | AK11: 90
A12: Verkooporder SO00454616 _ 3505026682.pdf | B12: Purchase Order Confirmation | C12: extracted | D12: 46080.56 | E12: 88.48 | F12: 143 | G12: 0 | I12: mail - info@g3-medical.nl — Verkooporder SO00454616 / 3505026682 | J12: Dutch | K12: 1 | L12: 3505026682 | M12: 98 | N12: SO00454616 | O12: 98 | P12: 16/02/2026 | Q12: 98 | R12: G3 Medical B.V. | S12: 95 | T12: Hospital Logistics Nederland B.V./Groene Hart Ziekenhuis | U12: 92 | V12: EUR | W12: 98 | X12: 1 | Y12: 98 | Z12: 700124 | AA12: 92 | AB12: Navelstrengklem, disposable, dubbele sluiting, blauw, steriel, 100x1st/ds | AC12: 88 | AD12: 3 | AE12: 96 | AF12: Dozen | AG12: 92 | AH12: 41,28 | AI12: 92 | AJ12: 19/02/2026 | AK12: 85
A13: Verkooporder SO00454616 _ 3505026682.pdf | B13: Purchase Order Confirmation | C13: extracted | D13: 46080.56 | E13: 88.48 | F13: 143 | G13: 0 | I13: mail - info@g3-medical.nl — Verkooporder SO00454616 / 3505026682 | J13: Dutch | K13: 2 | L13: 3505026682 | M13: 98 | N13: SO00454616 | O13: 98 | P13: 16/02/2026 | Q13: 98 | R13: G3 Medical B.V. | S13: 95 | T13: Hospital Logistics Nederland B.V./Groene Hart Ziekenhuis | U13: 92 | V13: EUR | W13: 98 | X13: 2 | Y13: 98 | Z13: 550269 | AA13: 90 | AB13: Noba 263106-1 gynaecologische tampon, 5mtr/6cm, steriel, 4x1st/ds | AC13: 86 | AD13: 8 | AE13: 96 | AF13: Dozen | AG13: 92 | AH13: 8,42 | AI13: 92 | AJ13: 19/02/2026 | AK13: 85
A14: Verkooporder SO00454616 _ 3505026682.pdf | B14: Purchase Order Confirmation | C14: extracted | D14: 46080.56 | E14: 88.48 | F14: 143 | G14: 0 | I14: mail - info@g3-medical.nl — Verkooporder SO00454616 / 3505026682 | J14: Dutch | K14: 3 | L14: 3505026682 | M14: 98 | N14: SO00454616 | O14: 98 | P14: 16/02/2026 | Q14: 98 | R14: G3 Medical B.V. | S14: 95 | T14: Hospital Logistics Nederland B.V./Groene Hart Ziekenhuis | U14: 92 | V14: EUR | W14: 98 | X14: 3 | Y14: 98 | Z14: 880421 | AA14: 90 | AB14: Swann Morton 0421, stitchcutter, 110mm, steriel, disposable, carbonstaal, per stuk, 100st/ds | AC14: 86 | AD14: 3 | AE14: 96 | AF14: Dozen | AG14: 92 | AH14: 30,83 | AI14: 90 | AJ14: 19/02/2026 | AK14: 85
... A22: Verkooporder SO00454616 _ 3505026682.pdf | B22: Purchase Order Confirmation | C22: extracted | D22: 46080.56 | E22: 88.48 | F22: 143 | G22: 0 | I22: mail - info@g3-medical.nl — Verkooporder SO00454616 / 3505026682 | J22: Dutch | K22: 11 | L22: 3505026682 | M22: 98 | N22: SO00454616 | O22: 98 | P22: 16/02/2026 | Q22: 98 | R22: G3 Medical B.V. | S22: 95 | T22: Hospital Logistics Nederland B.V./Groene Hart Ziekenhuis | U22: 92 | V22: EUR | W22: 98 | X22: 11 | Y22: 98 | Z22: MKKSS | AA22: 90 | AB22: HP MKK-SS Polsband met enkele bevestigingsband, 30 cm, p/pr | AC22: 88 | AD22: 7 | AE22: 96 | AF22: Paar | AG22: 92 | AH22: 9,90 | AI22: 90 | AJ22: 26/02/2026 | AK22: 96
A23: Re_ [EXTERNAL EMAIL] Order Hospital Logistics 1507018691.pdf | B23: Purchase Order Confirmation | C23: extracted | D23: 46080.559 | E23: 88.54 | F23: 78 | G23: 5 | I23: mail - orders.NL@freseniusmedicalcare.com — Re: [EXTERNAL EMAIL] Order Hospital Logistics 1507018691 | J23: Dutch | K23: 1 | L23: 1507018691 | M23: 98 | N23: 2364062865 | O23: 96 | P23: 16/02/2026 | Q23: 92 | R23: Fresenius Medical Care Nederland BV | S23: 92 | T23: Hospital Logistics, Medisch Centrum Leeuwarden | U23: 88 | V23: EUR | W23: 96 | X23: 10 | Y23: 95 | Z23: 5092030 | AA23: 95 | AB23: Prijs per behandeling BTW Laag | AC23: 90 | AD23: 240 | AE23: 94 | AF23: ST | AG23: 92 | AH23: 27,77 | AI23: 94 | AK23: 20
A24: Re_ [EXTERNAL EMAIL] Order Hospital Logistics 1507018691.pdf | B24: Purchase Order Confirmation | C24: extracted | D24: 46080.559 | E24: 88.54 | F24: 78 | G24: 5 | I24: mail - orders.NL@freseniusmedicalcare.com — Re: [EXTERNAL EMAIL] Order Hospital Logistics 1507018691 | J24: Dutch | K24: 2 | L24: 1507018691 | M24: 98 | N24: 2364062865 | O24: 96 | P24: 16/02/2026 | Q24: 92 | R24: Fresenius Medical Care Nederland BV | S24: 92 | T24: Hospital Logistics, Medisch Centrum Leeuwarden | U24: 88 | V24: EUR | W24: 96 | X24: 210 | Y24: 95 | Z24: 5060781 | AA24: 95 | AB24: BIBAG 650g 5008 | AC24: 92 | AD24: 240 | AE24: 94 | AF24: ST | AG24: 92 | AH24: 27,77 | AI24: 95 | AJ24: 17/02/2026 | AK24: 95
A25: Re_ [EXTERNAL EMAIL] Order Hospital Logistics 1507018691.pdf | B25: Purchase Order Confirmation | C25: extracted | D25: 46080.559 | E25: 88.54 | F25: 78 | G25: 5 | I25: mail - orders.NL@freseniusmedicalcare.com — Re: [EXTERNAL EMAIL] Order Hospital Logistics 1507018691 | J25: Dutch | K25: 3 | L25: 1507018691 | M25: 98 | N25: 2364062865 | O25: 96 | P25: 16/02/2026 | Q25: 92 | R25: Fresenius Medical Care Nederland BV | S25: 92 | T25: Hospital Logistics, Medisch Centrum Leeuwarden | U25: 88 | V25: EUR | W25: 96 | X25: 440 | Y25: 95 | Z25: F00001591 | AA25: 95 | AB25: FX CorDiax 80 | AC25: 90 | AD25: 240 | AE25: 90 | AF25: ST | AG25: 88 | AI25: 30 | AJ25: 17/02/2026 | AK25: 95
A26: Re_ [EXTERNAL EMAIL] Order Hospital Logistics 1507018691.pdf | B26: Purchase Order Confirmation | C26: extracted | D26: 46080.559 | E26: 88.54 | F26: 78 | G26: 5 | I26: mail - orders.NL@freseniusmedicalcare.com — Re: [EXTERNAL EMAIL] Order Hospital Logistics 1507018691 | J26: Dutch | K26: 4 | L26: 1507018691 | M26: 98 | N26: 2364062865 | O26: 96 | P26: 16/02/2026 | Q26: 92 | R26: Fresenius Medical Care Nederland BV | S26: 92 | T26: Hospital Logistics, Medisch Centrum Leeuwarden | U26: 88 | V26: EUR | W26: 96 | X26: 660 | Y26: 95 | Z26: 5092030ID | AA26: 95 | AB26: Prijs per behandeling BTW Hoog | AC26: 92 | AD26: 240 | AE26: 94 | AF26: ST | AG26: 92 | AH26: 4,34 | AI26: 95 | AK26: 25
A27: Re_ [EXTERNAL EMAIL] Order Hospital Logistics 1507018691.pdf | B27: Purchase Order Confirmation | C27: extracted | D27: 46080.559 | E27: 88.54 | F27: 78 | G27: 5 | I27: mail - orders.NL@freseniusmedicalcare.com — Re: [EXTERNAL EMAIL] Order Hospital Logistics 1507018691 | J27: Dutch | K27: 5 | L27: 1507018691 | M27: 98 | N27: 2364062865 | O27: 96 | P27: 16/02/2026 | Q27: 92 | R27: Fresenius Medical Care Nederland BV | S27: 92 | T27: Hospital Logistics, Medisch Centrum Leeuwarden | U27: 88 | V27: EUR | W27: 96 | X27: 730 | Y27: 95 | Z27: F00006822 | AA27: 95 | AB27: FX CorAL 80 | AC27: 92 | AD27: 72 | AE27: 94 | AF27: ST | AG27: 92 | AH27: 5,38 | AI27: 95 | AK27: 25
A28: Re_ [EXTERNAL EMAIL] Order Hospital Logistics 1507018691.pdf | B28: Purchase Order Confirmation | C28: extracted | D28: 46080.559 | E28: 88.54 | F28: 78 | G28: 5 | I28: mail - orders.NL@freseniusmedicalcare.com — Re: [EXTERNAL EMAIL] Order Hospital Logistics 1507018691 | J28: Dutch | K28: 6 | L28: 1507018691 | M28: 98 | N28: 2364062865 | O28: 96 | P28: 16/02/2026 | Q28: 92 | R28: Fresenius Medical Care Nederland BV | S28: 92 | T28: Hospital Logistics, Medisch Centrum Leeuwarden | U28: 88 | V28: EUR | W28: 96 | X28: 810 | Y28: 95 | Z28: F00001595 | AA28: 95 | AB28: FX CorDiax 1000 | AC28: 92 | AD28: 168 | AE28: 94 | AF28: ST | AG28: 92 | AH28: 1,28 | AI28: 95 | AK28: 20
A29: Re_ [EXTERNAL EMAIL] Order Hospital Logistics 3504015924.pdf | B29: Purchase Order Confirmation | C29: extracted | D29: 46080.559 | E29: 89.42 | F29: 39 | G29: 3 | I29: mail - orders.NL@freseniusmedicalcare.com — Re: [EXTERNAL EMAIL] Order Hospital Logistics 3504015924 | J29: Dutch | K29: 1 | L29: 3504015924 | M29: 95 | N29: 2364063103 | O29: 90 | P29: 16/02/2026 | Q29: 95 | R29: Fresenius Medical Care Nederland BV | S29: 95 | T29: Hospital Logistics Nederland | U29: 95 | V29: EUR | W29: 100 | X29: 10 | Y29: 95 | Z29: 5060781 | AA29: 95 | AB29: BIBAG 650g 5008 | AC29: 90 | AD29: 128 | AE29: 95 | AF29: ST | AG29: 90 | AH29: 2,89 | AI29: 95 | AK29: 20
A30: Re_ [EXTERNAL EMAIL] Order Hospital Logistics 3504015924.pdf | B30: Purchase Order Confirmation | C30: extracted | D30: 46080.559 | E30: 89.42 | F30: 39 | G30: 3 | I30: mail - orders.NL@freseniusmedicalcare.com — Re: [EXTERNAL EMAIL] Order Hospital Logistics 3504015924 | J30: Dutch | K30: 2 | L30: 3504015924 | M30: 95 | N30: 2364063103 | O30: 90 | P30: 16/02/2026 | Q30: 95 | R30: Fresenius Medical Care Nederland BV | S30: 95 | T30: Hospital Logistics Nederland | U30: 95 | V30: EUR | W30: 100 | X30: 20 | Y30: 95 | Z30: F00002387 | AA30: 95 | AB30: FX 80 classix | AC30: 90 | AD30: 48 | AE30: 95 | AF30: ST | AG30: 90 | AH30: 8,48 | AI30: 95 | AK30: 20
A31: Re_ [EXTERNAL EMAIL] Order Hospital Logistics 3504015924.pdf | B31: Purchase Order Confirmation | C31: extracted | D31: 46080.559 | E31: 89.42 | F31: 39 | G31: 3 | I31: mail - orders.NL@freseniusmedicalcare.com — Re: [EXTERNAL EMAIL] Order Hospital Logistics 3504015924 | J31: Dutch | K31: 3 | L31: 3504015924 | M31: 95 | N31: 2364063103 | O31: 90 | P31: 16/02/2026 | Q31: 95 | R31: Fresenius Medical Care Nederland BV | S31: 95 | T31: Hospital Logistics Nederland | U31: 95 | V31: EUR | W31: 100 | X31: 30 | Y31: 95 | Z31: 5060801 | AA31: 95 | AB31: BIBAG 900g 5008 | AC31: 90 | AD31: 84 | AE31: 95 | AF31: ST | AG31: 90 | AH31: 3,95 | AI31: 95 | AK31: 20
A32: 3505026639 ESSITY Orderbevestiging.pdf | B32: Purchase Order Confirmation | C32: extracted | D32: 46080.559 | E32: 64.8 | F32: 1140 | G32: 0 | I32: mail - tena.medical.cs.nl@essity.com — 3505026639 ESSITY Orderbevestiging | J32: Dutch | K32: 1 | L32: 3505026639 | M32: 50 | N32: 3004524437 | O32: 50 | P32: 11/02/2026 | Q32: 50 | R32: Essity Netherlands B.V. Health & Medical | S32: 50 | T32: Hospital Logistics Nederland b.v. | U32: 50 | V32: EUR | W32: 50 | X32: 10 | Y32: 50 | Z32: 7238101 | AA32: 50 | AB32: Leukomed T 8 x 10cm - P50 | AC32: 50 | AD32: 4 | AE32: 50 | AF32: PC | AG32: 50 | AH32: 18,77 / 1 PC | AI32: 50 | AJ32: 18/02/2026 | AK32: 50
A33: 3505026639 ESSITY Orderbevestiging.pdf | B33: Purchase Order Confirmation | C33: extracted | D33: 46080.559 | E33: 64.8 | F33: 1140 | G33: 0 | I33: mail - tena.medical.cs.nl@essity.com — 3505026639 ESSITY Orderbevestiging | J33: Dutch | K33: 2 | L33: 3505026639 | M33: 50 | N33: 3004524437 | O33: 50 | P33: 11/02/2026 | Q33: 50 | R33: Essity Netherlands B.V. Health & Medical | S33: 50 | T33: Hospital Logistics Nederland b.v. | U33: 50 | V33: EUR | W33: 50 | X33: 20 | Y33: 50 | Z33: 7268000 | AA33: 50 | AB33: Cuticell Contact 5 x 7,5cm - P5 | AC33: 50 | AD33: 60 | AE33: 50 | AF33: PC | AG33: 50 | AH33: 4,41 / 1 PC | AI33: 50 | AJ33: 18/02/2026 | AK33: 50
A34: 3505026639 ESSITY Orderbevestiging.pdf | B34: Purchase Order Confirmation | C34: extracted | D34: 46080.559 | E34: 64.8 | F34: 1140 | G34: 0 | I34: mail - tena.medical.cs.nl@essity.com — 3505026639 ESSITY Orderbevestiging | J34: Dutch | K34: 3 | L34: 3505026639 | M34: 50 | N34: 3004524437 | O34: 50 | P34: 11/02/2026 | Q34: 50 | R34: Essity Netherlands B.V. Health & Medical | S34: 50 | T34: Hospital Logistics Nederland b.v. | U34: 50 | V34: EUR | W34: 50 | X34: 30 | Y34: 50 | Z34: 7123718 | AA34: 50 | AB34: LP comp cot gauze ST 10x20cm 12PLY - P50x1 | AC34: 50 | AD34: 3 | AE34: 50 | AF34: PC | AG34: 50 | AH34: 8,71 / 1 PC | AI34: 50
A35: 3505026639 ESSITY Orderbevestiging.pdf | B35: Purchase Order Confirmation | C35: extracted | D35: 46080.559 | E35: 64.8 | F35: 1140 | G35: 0 | I35: mail - tena.medical.cs.nl@essity.com — 3505026639 ESSITY Orderbevestiging | J35: Dutch | K35: 4 | L35: 3505026639 | M35: 50 | N35: 3004524437 | O35: 50 | P35: 11/02/2026 | Q35: 50 | R35: Essity Netherlands B.V. Health & Medical | S35: 50 | T35: Hospital Logistics Nederland b.v. | U35: 50 | V35: EUR | W35: 50 | X35: 40 | Y35: 50 | Z35: 7274007 | AA35: 50 | AB35: LP WCS ST natural 6x75mm - P50x3 strips | AC35: 50 | AD35: 2 | AE35: 50 | AF35: PC | AG35: 50 | AH35: 26,35 / 1 PC | AI35: 50 | AJ35: 18/02/2026 | AK35: 50
A36: 3505026639 ESSITY Orderbevestiging.pdf | B36: Purchase Order Confirmation | C36: extracted | D36: 46080.559 | E36: 64.8 | F36: 1140 | G36: 0 | I36: mail - tena.medical.cs.nl@essity.com — 3505026639 ESSITY Orderbevestiging | J36: Dutch | K36: 5 | L36: 3505026639 | M36: 50 | N36: 3004524437 | O36: 50 | P36: 11/02/2026 | Q36: 50 | R36: Essity Netherlands B.V. Health & Medical | S36: 50 | T36: Hospital Logistics Nederland b.v. | U36: 50 | V36: EUR | W36: 50 | X36: 50 | Y36: 50 | Z36: 7274006 | AA36: 50 | AB36: LP WCS ST natural 6x38mm - P50x6 strips | AC36: 50 | AD36: 2 | AE36: 50 | AF36: PC | AG36: 50 | AH36: 28,19 / 1 PC | AI36: 50 | AJ36: 18/02/2026 | AK36: 50
A37: 3505026639 ESSITY Orderbevestiging.pdf | B37: Purchase Order Confirmation | C37: extracted | D37: 46080.559 | E37: 64.8 | F37: 1140 | G37: 0 | I37: mail - tena.medical.cs.nl@essity.com — 3505026639 ESSITY Orderbevestiging | J37: Dutch | K37: 6 | L37: 3505026639 | M37: 50 | N37: 3004524437 | O37: 50 | P37: 11/02/2026 | Q37: 50 | R37: Essity Netherlands B.V. Health & Medical | S37: 50 | T37: Hospital Logistics Nederland b.v. | U37: 50 | V37: EUR | W37: 50 | X37: 60 | Y37: 50 | Z37: 7274008 | AA37: 50 | AB37: LP WCS ST natural 12x100mm - P50x6 strips | AC37: 50 | AD37: 2 | AE37: 50 | AF37: PC | AG37: 50 | AH37: 36,16 / 1 PC | AI37: 50 | AJ37: 18/02/2026 | AK37: 50
A38: 3505026639 ESSITY Orderbevestiging.pdf | B38: Purchase Order Confirmation | C38: extracted | D38: 46080.559 | E38: 64.8 | F38: 1140 | G38: 0 | I38: mail - tena.medical.cs.nl@essity.com — 3505026639 ESSITY Orderbevestiging | J38: Dutch | K38: 7 | L38: 3505026639 | M38: 50 | N38: 3004524437 | O38: 50 | P38: 11/02/2026 | Q38: 50 | R38: Essity Netherlands B.V. Health & Medical | S38: 50 | T38: Hospital Logistics Nederland b.v. | U38: 50 | V38: EUR | W38: 50 | X38: 70 | Y38: 50 | Z38: 7128201 | AA38: 50 | AB38: LP comp abs protect ST 20 x 40cm - P25x1 | AC38: 50 | AD38: 7 | AE38: 50 | AF38: PC | AG38: 50 | AH38: 14,28 / 1 PC | AI38: 50 | AJ38: 18/02/2026 | AK38: 50
A39: 3505026639 ESSITY Orderbevestiging.pdf | B39: Purchase Order Confirmation | C39: extracted | D39: 46080.559 | E39: 64.8 | F39: 1140 | G39: 0 | I39: mail - tena.medical.cs.nl@essity.com — 3505026639 ESSITY Orderbevestiging | J39: Dutch | K39: 8 | L39: 3505026639 | M39: 50 | N39: 3004524437 | O39: 50 | P39: 11/02/2026 | Q39: 50 | R39: Essity Netherlands B.V. Health & Medical | S39: 50 | T39: Hospital Logistics Nederland b.v. | U39: 50 | V39: EUR | W39: 50 | X39: 80 | Y39: 50 | Z39: 7128203 | AA39: 50 | AB39: LP comp abs protect ST 10 x 20cm - P50x1 | AC39: 50 | AD39: 24 | AE39: 50 | AF39: PC | AG39: 50 | AH39: 9,29 / 1 PC | AI39: 50 | AJ39: 18/02/2026 | AK39: 50
A40: 3505026639 ESSITY Orderbevestiging.pdf | B40: Purchase Order Confirmation | C40: extracted | D40: 46080.559 | E40: 64.8 | F40: 1140 | G40: 0 | I40: mail - tena.medical.cs.nl@essity.com — 3505026639 ESSITY Orderbevestiging | J40: Dutch | K40: 9 | L40: 3505026639 | M40: 50 | N40: 3004524437 | O40: 50 | P40: 11/02/2026 | Q40: 50 | R40: Essity Netherlands B.V. Health & Medical | S40: 50 | T40: Hospital Logistics Nederland b.v. | U40: 50 | V40: EUR | W40: 50 | X40: 90 | Y40: 50 | Z40: 7128814 | AA40: 50 | AB40: LP comp non-wov ST 10x10cm 4PLY - P25x10 | AC40: 50 | AD40: 15 | AE40: 50 | AF40: PC | AG40: 50 | AH40: 5,95 / 1 PC | AI40: 50 | AJ40: 18/02/2026 | AK40: 50
A41: 3505026639 ESSITY Orderbevestiging.pdf | B41: Purchase Order Confirmation | C41: extracted | D41: 46080.559 | E41: 64.8 | F41: 1140 | G41: 0 | I41: mail - tena.medical.cs.nl@essity.com — 3505026639 ESSITY Orderbevestiging | J41: Dutch | K41: 10 | L41: 3505026639 | M41: 50 | N41: 3004524437 | O41: 50 | P41: 11/02/2026 | Q41: 50 | R41: Essity Netherlands B.V. Health & Medical | S41: 50 | T41: Hospital Logistics Nederland b.v. | U41: 50 | V41: EUR | W41: 50 | X41: 100 | Y41: 50 | Z41: 7228001 | AA41: 50 | AB41: DC Conformable wit 3,6m x 5cm - P10 | AC41: 50 | AD41: 7 | AE41: 50 | AF41: PC | AG41: 50 | AH41: 50,25 / 1 PC | AI41: 50 | AJ41: 18/02/2026 | AK41: 50
A42: 3505026639 ESSITY Orderbevestiging.pdf | B42: Purchase Order Confirmation | C42: extracted | D42: 46080.559 | E42: 64.8 | F42: 1140 | G42: 0 | I42: mail - tena.medical.cs.nl@essity.com — 3505026639 ESSITY Orderbevestiging | J42: Dutch | K42: 11 | L42: 3505026639 | M42: 50 | N42: 3004524437 | O42: 50 | P42: 11/02/2026 | Q42: 50 | R42: Essity Netherlands B.V. Health & Medical | S42: 50 | T42: Hospital Logistics Nederland b.v. | U42: 50 | V42: EUR | W42: 50 | X42: 110 | Y42: 50 | Z42: 7228002 | AA42: 50 | AB42: DC Conformable wit 3,6m x 7,5cm - P10 | AC42: 50 | AD42: 16 | AE42: 50 | AF42: PC | AG42: 50 | AH42: 61,49 / 1 PC | AI42: 50 | AJ42: 18/02/2026 | AK42: 50
A43: 3505026639 ESSITY Orderbevestiging.pdf | B43: Purchase Order Confirmation | C43: extracted | D43: 46080.559 | E43: 64.8 | F43: 1140 | G43: 0 | I43: mail - tena.medical.cs.nl@essity.com — 3505026639 ESSITY Orderbevestiging | J43: Dutch | K43: 12 | L43: 3505026639 | M43: 50 | N43: 3004524437 | O43: 50 | P43: 11/02/2026 | Q43: 50 | R43: Essity Netherlands B.V. Health & Medical | S43: 50 | T43: Hospital Logistics Nederland b.v. | U43: 50 | V43: EUR | W43: 50 | X43: 120 | Y43: 50 | Z43: 7228003 | AA43: 50 | AB43: DC Conformable wit 3,6m x 10cm - P10 | AC43: 50 | AD43: 7 | AE43: 50 | AF43: PC | AG43: 50 | AH43: 72,23 / 1 PC | AI43: 50 | AJ43: 18/02/2026 | AK43: 50
A44: 3505026639 ESSITY Orderbevestiging.pdf | B44: Purchase Order Confirmation | C44: extracted | D44: 46080.559 | E44: 64.8 | F44: 1140 | G44: 0 | I44: mail - tena.medical.cs.nl@essity.com — 3505026639 ESSITY Orderbevestiging | J44: Dutch | K44: 13 | L44: 3505026639 | M44: 50 | N44: 3004524437 | O44: 50 | P44: 11/02/2026 | Q44: 50 | R44: Essity Netherlands B.V. Health & Medical | S44: 50 | T44: Hospital Logistics Nederland b.v. | U44: 50 | V44: EUR | W44: 50 | X44: 130 | Y44: 50 | Z44: 7228004 | AA44: 50 | AB44: DC Conformable wit 3,6m x 12,5cm - P10 | AC44: 50 | AD44: 3 | AE44: 50 | AF44: PC | AG44: 50 | AH44: 79,79 / 1 PC | AI44: 50 | AJ44: 18/02/2026 | AK44: 50
A45: 3505026639 ESSITY Orderbevestiging.pdf | B45: Purchase Order Confirmation | C45: extracted | D45: 46080.559 | E45: 64.8 | F45: 1140 | G45: 0 | I45: mail - tena.medical.cs.nl@essity.com — 3505026639 ESSITY Orderbevestiging | J45: Dutch | K45: 14 | L45: 3505026639 | M45: 50 | N45: 3004524437 | O45: 50 | P45: 11/02/2026 | Q45: 50 | R45: Essity Netherlands B.V. Health & Medical | S45: 50 | T45: Hospital Logistics Nederland b.v. | U45: 50 | V45: EUR | W45: 50 | X45: 140 | Y45: 50 | Z45: 7228601 | AA45: 50 | AB45: DC Conformable paars 3,6m x 7,5cm - P10 | AC45: 50 | AD45: 2 | AE45: 50 | AF45: PC | AG45: 50 | AH45: 67,13 / 1 PC | AI45: 50 | AJ45: 18/02/2026 | AK45: 50
A46: 3505026639 ESSITY Orderbevestiging.pdf | B46: Purchase Order Confirmation | C46: extracted | D46: 46080.559 | E46: 64.8 | F46: 1140 | G46: 0 | I46: mail - tena.medical.cs.nl@essity.com — 3505026639 ESSITY Orderbevestiging | J46: Dutch | K46: 15 | L46: 3505026639 | M46: 50 | N46: 3004524437 | O46: 50 | P46: 11/02/2026 | Q46: 50 | R46: Essity Netherlands B.V. Health & Medical | S46: 50 | T46: Hospital Logistics Nederland b.v. | U46: 50 | V46: EUR | W46: 50 | X46: 150 | Y46: 50 | Z46: 7228801 | AA46: 50 | AB46: DCC zwart 3,6m x 7,5cm - P10 | AC46: 50 | AD46: 4 | AE46: 50 | AF46: PC | AG46: 50 | AH46: 62,74 / 1 PC | AI46: 50 | AJ46: 18/02/2026 | AK46: 50
... A75: 3505026639 ESSITY Orderbevestiging.pdf | B75: Purchase Order Confirmation | C75: extracted | D75: 46080.559 | E75: 64.8 | F75: 1140 | G75: 0 | I75: mail - tena.medical.cs.nl@essity.com — 3505026639 ESSITY Orderbevestiging | J75: Dutch | K75: 44 | L75: 3505026639 | M75: 50 | N75: 3004524437 | O75: 50 | P75: 11/02/2026 | Q75: 50 | R75: Essity Netherlands B.V. Health & Medical | S75: 50 | T75: Hospital Logistics Nederland b.v. | U75: 50 | V75: EUR | W75: 50 | X75: 440 | Y75: 50 | Z75: 7702800 | AA75: 50 | AB75: Comprinet pro knie groot wit 1pr | AC75: 50 | AD75: 10 | AE75: 50 | AF75: PC | AG75: 50 | AH75: 5,17 / 1 PC | AI75: 50 | AJ75: 18/02/2026 | AK75: 50
...

Sheet Pivot
A3: File Name | B3: Document Type | C3: Status | D3: Count of Line Item # | E3: Count of Purchase Order Number | F3: Count of Supplier Order Number | G3: Count of Order Date | H3: Count of Supplier Name | I3: Count of Customer Name | J3: Count of Currency | K3: Count of Article Number | L3: Count of Item Description | M3: Count of Quantity | N3: Count of Unit of Measure | O3: Count of Unit Price | P3: Count of Item Planned Delivery Date | Q3: % of Purchase Order Number | R3: % of Supplier Order Number | S3: % of Order Date | T3: % of Supplier Name | U3: % of Customer Name | V3: % of Currency | W3: % of Article Number | X3: % of Item Description | Y3: % of Quantity | Z3: % of Unit of Measure | AA3: % of Unit Price | AB3: % of Item Planned Delivery Date
A4: _ Orderbevestiging 1501037327.pdf | B4: Purchase Order Confirmation | C4: extracted | D4: 1 | E4: 1 | F4: 1 | G4: 1 | H4: 1 | I4: 1 | J4: 1 | K4: 1 | L4: 1 | M4: 1 | N4: 1 | O4: 1 | P4: 1 | Q4: =GETPIVOTDATA("Count of Line Item #",$A$3,"File Name",$A4)/GETPIVOTDATA("Count of Purchase Order Number",$A$3,"File Name",$A4) -> 1 | R4: =GETPIVOTDATA("Count of Line Item #",$A$3,"File Name",$A4)/GETPIVOTDATA("Count of Supplier Order Number",$A$3,"File Name",$A4) -> 1 | S4: =GETPIVOTDATA("Count of Line Item #",$A$3,"File Name",$A4)/GETPIVOTDATA("Count of Order Date",$A$3,"File Name",$A4) -> 1 | T4: =GETPIVOTDATA("Count of Line Item #",$A$3,"File Name",$A4)/GETPIVOTDATA("Count of Supplier Name",$A$3,"File Name",$A4) -> 1 | U4: =GETPIVOTDATA("Count of Line Item #",$A$3,"File Name",$A4)/GETPIVOTDATA("Count of Customer Name",$A$3,"File Name",$A4) -> 1 | V4: =GETPIVOTDATA("Count of Line Item #",$A$3,"File Name",$A4)/GETPIVOTDATA("Count of Currency",$A$3,"File Name",$A4) -> 1 | W4: =GETPIVOTDATA("Count of Line Item #",$A$3,"File Name",$A4)/GETPIVOTDATA("Count of Article Number",$A$3,"File Name",$A4) -> 1 | X4: =GETPIVOTDATA("Count of Line Item #",$A$3,"File Name",$A4)/GETPIVOTDATA("Count of Item Description",$A$3,"File Name",$A4) -> 1 | Y4: =GETPIVOTDATA("Count of Line Item #",$A$3,"File Name",$A4)/GETPIVOTDATA("Count of Quantity",$A$3,"File Name",$A4) -> 1 | Z4: =GETPIVOTDATA("Count of Line Item #",$A$3,"File Name",$A4)/GETPIVOTDATA("Count of Unit of Measure",$A$3,"File Name",$A4) -> 1 | AA4: =GETPIVOTDATA("Count of Line Item #",$A$3,"File Name",$A4)/GETPIVOTDATA("Count of Unit Price",$A$3,"File Name",$A4) -> 1 | AB4: =GETPIVOTDATA("Count of Item Planned Delivery Date",$A$3,"File Name",$A4)/GETPIVOTDATA("Count of Line Item #",$A$3,"File Name",$A4) -> 1
A5: _ Orderbevestiging 1504026582.pdf | B5: Purchase Order Confirmation | C5: extracted | D5: 1 | E5: 1 | F5: 1 | G5: 1 | H5: 1 | I5: 1 | J5: 1 | K5: 1 | L5: 1 | M5: 1 | N5: 1 | O5: 1 | P5: 1 | Q5: =GETPIVOTDATA("Count of Line Item #",$A$3,"File Name",$A5)/GETPIVOTDATA("Count of Purchase Order Number",$A$3,"File Name",$A5) -> 1 | R5: =GETPIVOTDATA("Count of Line Item #",$A$3,"File Name",$A5)/GETPIVOTDATA("Count of Supplier Order Number",$A$3,"File Name",$A5) -> 1 | S5: =GETPIVOTDATA("Count of Line Item #",$A$3,"File Name",$A5)/GETPIVOTDATA("Count of Order Date",$A$3,"File Name",$A5) -> 1 | T5: =GETPIVOTDATA("Count of Line Item #",$A$3,"File Name",$A5)/GETPIVOTDATA("Count of Supplier Name",$A$3,"File Name",$A5) -> 1 | U5: =GETPIVOTDATA("Count of Line Item #",$A$3,"File Name",$A5)/GETPIVOTDATA("Count of Customer Name",$A$3,"File Name",$A5) -> 1 | V5: =GETPIVOTDATA("Count of Line Item #",$A$3,"File Name",$A5)/GETPIVOTDATA("Count of Currency",$A$3,"File Name",$A5) -> 1 | W5: =GETPIVOTDATA("Count of Line Item #",$A$3,"File Name",$A5)/GETPIVOTDATA("Count of Article Number",$A$3,"File Name",$A5) -> 1 | X5: =GETPIVOTDATA("Count of Line Item #",$A$3,"File Name",$A5)/GETPIVOTDATA("Count of Item Description",$A$3,"File Name",$A5) -> 1 | Y5: =GETPIVOTDATA("Count of Line Item #",$A$3,"File Name",$A5)/GETPIVOTDATA("Count of Quantity",$A$3,"File Name",$A5) -> 1 | Z5: =GETPIVOTDATA("Count of Line Item #",$A$3,"File Name",$A5)/GETPIVOTDATA("Count of Unit of Measure",$A$3,"File Name",$A5) -> 1 | AA5: =GETPIVOTDATA("Count of Line Item #",$A$3,"File Name",$A5)/GETPIVOTDATA("Count of Unit Price",$A$3,"File Name",$A5) -> 1 | AB5: =GETPIVOTDATA("Count of Item Planned Delivery Date",$A$3,"File Name",$A5)/GETPIVOTDATA("Count of Line Item #",$A$3,"File Name",$A5) -> 1
A6: _ Orderbevestiging 1505040022.pdf | B6: Purchase Order Confirmation | C6: extracted | D6: 2 | E6: 2 | F6: 2 | G6: 2 | H6: 2 | I6: 2 | J6: 2 | K6: 2 | L6: 2 | M6: 2 | N6: 2 | O6: 2 | P6: 2 | Q6: =GETPIVOTDATA("Count of Line Item #",$A$3,"File Name",$A6)/GETPIVOTDATA("Count of Purchase Order Number",$A$3,"File Name",$A6) -> 1 | R6: =GETPIVOTDATA("Count of Line Item #",$A$3,"File Name",$A6)/GETPIVOTDATA("Count of Supplier Order Number",$A$3,"File Name",$A6) -> 1 | S6: =GETPIVOTDATA("Count of Line Item #",$A$3,"File Name",$A6)/GETPIVOTDATA("Count of Order Date",$A$3,"File Name",$A6) -> 1 | T6: =GETPIVOTDATA("Count of Line Item #",$A$3,"File Name",$A6)/GETPIVOTDATA("Count of Supplier Name",$A$3,"File Name",$A6) -> 1 | U6: =GETPIVOTDATA("Count of Line Item #",$A$3,"File Name",$A6)/GETPIVOTDATA("Count of Customer Name",$A$3,"File Name",$A6) -> 1 | V6: =GETPIVOTDATA("Count of Line Item #",$A$3,"File Name",$A6)/GETPIVOTDATA("Count of Currency",$A$3,"File Name",$A6) -> 1 | W6: =GETPIVOTDATA("Count of Line Item #",$A$3,"File Name",$A6)/GETPIVOTDATA("Count of Article Number",$A$3,"File Name",$A6) -> 1 | X6: =GETPIVOTDATA("Count of Line Item #",$A$3,"File Name",$A6)/GETPIVOTDATA("Count of Item Description",$A$3,"File Name",$A6) -> 1 | Y6: =GETPIVOTDATA("Count of Line Item #",$A$3,"File Name",$A6)/GETPIVOTDATA("Count of Quantity",$A$3,"File Name",$A6) -> 1 | Z6: =GETPIVOTDATA("Count of Line Item #",$A$3,"File Name",$A6)/GETPIVOTDATA("Count of Unit of Measure",$A$3,"File Name",$A6) -> 1 | AA6: =GETPIVOTDATA("Count of Line Item #",$A$3,"File Name",$A6)/GETPIVOTDATA("Count of Unit Price",$A$3,"File Name",$A6) -> 1 | AB6: =GETPIVOTDATA("Count of Item Planned Delivery Date",$A$3,"File Name",$A6)/GETPIVOTDATA("Count of Line Item #",$A$3,"File Name",$A6) -> 1
